Workbook

Sheet Ventas
A1: Ferretería Don José — Registro de Ventas Mensuales 2024
A2: Datos de demostración — generados automáticamente con Python
A4: Mes | B4: Producto | C4: Categoría | D4: Unidades vendidas | E4: Precio unit. ($) | F4: Ingreso ($) | G4: Costo ($) | H4: Ganancia ($)
A5: Enero | B5: Tornillos 6x1 (caja x100) | C5: Fijaciones | D5: 936 | E5: 1.2 | F5: =D5*E5 | G5: =D5*0.45 | H5: =F5-G5
A6: Enero | B6: Pintura látex blanca 4L | C6: Pinturas | D6: 236 | E6: 18.5 | F6: =D6*E6 | G6: =D6*9.8 | H6: =F6-G6
A7: Enero | B7: Llave combinada 13mm | C7: Herramientas | D7: 130 | E7: 12 | F7: =D7*E7 | G7: =D7*5.5 | H7: =F7-G7
A8: Enero | B8: Cinta métrica 5m | C8: Medición | D8: 192 | E8: 8.9 | F8: =D8*E8 | G8: =D8*3.2 | H8: =F8-G8
A9: Enero | B9: Taladro percutor 650W | C9: Eléctricos | D9: 48 | E9: 89 | F9: =D9*E9 | G9: =D9*52.0 | H9: =F9-G9
A10: Enero | B10: Tubo PVC 110mm x 6m | C10: Plomería | D10: 201 | E10: 22 | F10: =D10*E10 | G10: =D10*11.5 | H10: =F10-G10
A11: Enero | B11: Lija al agua grano 120 | C11: Abrasivos | D11: 669 | E11: 1.8 | F11: =D11*E11 | G11: =D11*0.6 | H11: =F11-G11
A12: Enero | B12: Cerradura doble paleta | C12: Seguridad | D12: 78 | E12: 35 | F12: =D12*E12 | G12: =D12*17.0 | H12: =F12-G12
A13: Febrero | B13: Tornillos 6x1 (caja x100) | C13: Fijaciones | D13: 834 | E13: 1.2 | F13: =D13*E13 | G13: =D13*0.45 | H13: =F13-G13
A14: Febrero | B14: Pintura látex blanca 4L | C14: Pinturas | D14: 237 | E14: 18.5 | F14: =D14*E14 | G14: =D14*9.8 | H14: =F14-G14
A15: Febrero | B15: Llave combinada 13mm | C15: Herramientas | D15: 126 | E15: 12 | F15: =D15*E15 | G15: =D15*5.5 | H15: =F15-G15
A16: Febrero | B16: Cinta métrica 5m | C16: Medición | D16: 226 | E16: 8.9 | F16: =D16*E16 | G16: =D16*3.2 | H16: =F16-G16
A17: Febrero | B17: Taladro percutor 650W | C17: Eléctricos | D17: 32 | E17: 89 | F17: =D17*E17 | G17: =D17*52.0 | H17: =F17-G17
A18: Febrero | B18: Tubo PVC 110mm x 6m | C18: Plomería | D18: 154 | E18: 22 | F18: =D18*E18 | G18: =D18*11.5 | H18: =F18-G18
A19: Febrero | B19: Lija al agua grano 120 | C19: Abrasivos | D19: 598 | E19: 1.8 | F19: =D19*E19 | G19: =D19*0.6 | H19: =F19-G19
A20: Febrero | B20: Cerradura doble paleta | C20: Seguridad | D20: 102 | E20: 35 | F20: =D20*E20 | G20: =D20*17.0 | H20: =F20-G20
A21: Marzo | B21: Tornillos 6x1 (caja x100) | C21: Fijaciones | D21: 740 | E21: 1.2 | F21: =D21*E21 | G21: =D21*0.45 | H21: =F21-G21
A22: Marzo | B22: Pintura látex blanca 4L | C22: Pinturas | D22: 332 | E22: 18.5 | F22: =D22*E22 | G22: =D22*9.8 | H22: =F22-G22
A23: Marzo | B23: Llave combinada 13mm | C23: Herramientas | D23: 173 | E23: 12 | F23: =D23*E23 | G23: =D23*5.5 | H23: =F23-G23
A24: Marzo | B24: Cinta métrica 5m | C24: Medición | D24: 165 | E24: 8.9 | F24: =D24*E24 | G24: =D24*3.2 | H24: =F24-G24
A25: Marzo | B25: Taladro percutor 650W | C25: Eléctricos | D25: 50 | E25: 89 | F25: =D25*E25 | G25: =D25*52.0 | H25: =F25-G25
A26: Marzo | B26: Tubo PVC 110mm x 6m | C26: Plomería | D26: 204 | E26: 22 | F26: =D26*E26 | G26: =D26*11.5 | H26: =F26-G26
A27: Marzo | B27: Lija al agua grano 120 | C27: Abrasivos | D27: 506 | E27: 1.8 | F27: =D27*E27 | G27: =D27*0.6 | H27: =F27-G27
A28: Marzo | B28: Cerradura doble paleta | C28: Seguridad | D28: 81 | E28: 35 | F28: =D28*E28 | G28: =D28*17.0 | H28: =F28-G28
A29: Abril | B29: Tornillos 6x1 (caja x100) | C29: Fijaciones | D29: 1084 | E29: 1.2 | F29: =D29*E29 | G29: =D29*0.45 | H29: =F29-G29
A30: Abril | B30: Pintura látex blanca 4L | C30: Pinturas | D30: 289 | E30: 18.5 | F30: =D30*E30 | G30: =D30*9.8 | H30: =F30-G30
A31: Abril | B31: Llave combinada 13mm | C31: Herramientas | D31: 116 | E31: 12 | F31: =D31*E31 | G31: =D31*5.5 | H31: =F31-G31
A32: Abril | B32: Cinta métrica 5m | C32: Medición | D32: 176 | E32: 8.9 | F32: =D32*E32 | G32: =D32*3.2 | H32: =F32-G32
A33: Abril | B33: Taladro percutor 650W | C33: Eléctricos | D33: 51 | E33: 89 | F33: =D33*E33 | G33: =D33*52.0 | H33: =F33-G33
A34: Abril | B34: Tubo PVC 110mm x 6m | C34: Plomería | D34: 194 | E34: 22 | F34: =D34*E34 | G34: =D34*11.5 | H34: =F34-G34
A35: Abril | B35: Lija al agua grano 120 | C35: Abrasivos | D35: 644 | E35: 1.8 | F35: =D35*E35 | G35: =D35*0.6 | H35: =F35-G35
A36: Abril | B36: Cerradura doble paleta | C36: Seguridad | D36: 112 | E36: 35 | F36: =D36*E36 | G36: =D36*17.0 | H36: =F36-G36
A37: Mayo | B37: Tornillos 6x1 (caja x100) | C37: Fijaciones | D37: 888 | E37: 1.2 | F37: =D37*E37 | G37: =D37*0.45 | H37: =F37-G37
A38: Mayo | B38: Pintura látex blanca 4L | C38: Pinturas | D38: 398 | E38: 18.5 | F38: =D38*E38 | G38: =D38*9.8 | H38: =F38-G38
A39: Mayo | B39: Llave combinada 13mm | C39: Herramientas | D39: 138 | E39: 12 | F39: =D39*E39 | G39: =D39*5.5 | H39: =F39-G39
A40: Mayo | B40: Cinta métrica 5m | C40: Medición | D40: 231 | E40: 8.9 | F40: =D40*E40 | G40: =D40*3.2 | H40: =F40-G40
A41: Mayo | B41: Taladro percutor 650W | C41: Eléctricos | D41: 50 | E41: 89 | F41: =D41*E41 | G41: =D41*52.0 | H41: =F41-G41
...

Sheet Resumen mensual
A1: Resumen de ingresos y ganancias por mes
A3: Mes | B3: Ingresos ($) | C3: Costos ($) | D3: Ganancia ($)
A4: Enero | B4: =SUMIF(Ventas!A:A,A4,Ventas!F:F) | C4: =SUMIF(Ventas!A:A,A4,Ventas!G:G) | D4: =B4-C4
A5: Febrero | B5: =SUMIF(Ventas!A:A,A5,Ventas!F:F) | C5: =SUMIF(Ventas!A:A,A5,Ventas!G:G) | D5: =B5-C5
A6: Marzo | B6: =SUMIF(Ventas!A:A,A6,Ventas!F:F) | C6: =SUMIF(Ventas!A:A,A6,Ventas!G:G) | D6: =B6-C6
A7: Abril | B7: =SUMIF(Ventas!A:A,A7,Ventas!F:F) | C7: =SUMIF(Ventas!A:A,A7,Ventas!G:G) | D7: =B7-C7
A8: Mayo | B8: =SUMIF(Ventas!A:A,A8,Ventas!F:F) | C8: =SUMIF(Ventas!A:A,A8,Ventas!G:G) | D8: =B8-C8
A9: Junio | B9: =SUMIF(Ventas!A:A,A9,Ventas!F:F) | C9: =SUMIF(Ventas!A:A,A9,Ventas!G:G) | D9: =B9-C9
A10: Julio | B10: =SUMIF(Ventas!A:A,A10,Ventas!F:F) | C10: =SUMIF(Ventas!A:A,A10,Ventas!G:G) | D10: =B10-C10
A11: Agosto | B11: =SUMIF(Ventas!A:A,A11,Ventas!F:F) | C11: =SUMIF(Ventas!A:A,A11,Ventas!G:G) | D11: =B11-C11
A12: Septiembre | B12: =SUMIF(Ventas!A:A,A12,Ventas!F:F) | C12: =SUMIF(Ventas!A:A,A12,Ventas!G:G) | D12: =B12-C12
A13: Octubre | B13: =SUMIF(Ventas!A:A,A13,Ventas!F:F) | C13: =SUMIF(Ventas!A:A,A13,Ventas!G:G) | D13: =B13-C13
A14: Noviembre | B14: =SUMIF(Ventas!A:A,A14,Ventas!F:F) | C14: =SUMIF(Ventas!A:A,A14,Ventas!G:G) | D14: =B14-C14
A15: Diciembre | B15: =SUMIF(Ventas!A:A,A15,Ventas!F:F) | C15: =SUMIF(Ventas!A:A,A15,Ventas!G:G) | D15: =B15-C15
